<?xml version="1.0" ?>
<robot xmlns:xacro="http://www.ros.org/wiki/xacro">

  <!-- 공통 include -->
  <xacro:include filename="$(find amber_urdf_description)/urdf/materials.xacro" />

  <xacro:macro name="amber_urdf" params="prefix parent_link x y z roll pitch yaw">

    <!-- arm base link -->
    <link name="${prefix}base_link">
      <inertial>
        <origin rpy="0 0 0" xyz="3.041253315481396e-05 3.5233638099900425e-06 0.034386377739529544"/>
        <mass value="0.28897197894505794"/>
        <inertia ixx="0.000561" ixy="-0.0" ixz="-0.0" iyy="0.000389" iyz="0.0" izz="0.000553"/>
      </inertial>
      <visual>
        <origin rpy="0 0 0" xyz="0 0 0"/>
        <geometry>
          <mesh filename="package://amber_urdf_description/meshes/base_link.stl" scale="0.001 0.001 0.001"/>
        </geometry>
        <material name="silver_default"/>
      </visual>
      <collision>
        <origin rpy="0 0 0" xyz="0 0 0"/>
        <geometry>
          <mesh filename="package://amber_urdf_description/meshes/base_link.stl" scale="0.001 0.001 0.001"/>
        </geometry>
      </collision>
    </link>

    <joint name="${prefix}arm_mount" type="fixed">
      <origin rpy="${roll} ${pitch} ${yaw}" xyz="${x} ${y} ${z}"/>
      <parent link="${parent_link}"/>
      <child link="${prefix}base_link"/>
    </joint>

    <link name="${prefix}DOF1_1">
      <inertial>
        <origin rpy="0 0 0" xyz="-0.00015960906550393172 -1.2427845014393095e-05 -0.030235806886676903"/>
        <mass value="0.6510136315044379"/>
        <inertia ixx="0.000498" ixy="0.0" ixz="-3e-06" iyy="0.000484" iyz="-0.0" izz="0.000407"/>
      </inertial>
      <visual>
        <origin rpy="0 0 0" xyz="-0.0 -4e-06 -0.069966"/>
        <geometry>
          <mesh filename="package://amber_urdf_description/meshes/DOF1_1.stl" scale="0.001 0.001 0.001"/>
        </geometry>
        <material name="silver_default"/>
      </visual>
      <collision>
        <origin rpy="0 0 0" xyz="-0.0 -4e-06 -0.069966"/>
        <geometry>
          <mesh filename="package://amber_urdf_description/meshes/DOF1_1.stl" scale="0.001 0.001 0.001"/>
        </geometry>
      </collision>
    </link>

    <link name="${prefix}DOF1_LINK_1">
      <inertial>
        <origin rpy="0 0 0" xyz="5.2085527568610045e-06 0.004977895400043735 0.07010343107502044"/>
        <mass value="0.935292940405524"/>
        <inertia ixx="0.001224" ixy="-0.0" ixz="-0.0" iyy="0.001136" iyz="-4.3e-05" izz="0.00072"/>
      </inertial>
      <visual>
        <origin rpy="0 0 0" xyz="-0.0 -4e-06 -0.074366"/>
        <geometry>
          <mesh filename="package://amber_urdf_description/meshes/DOF1_LINK_1.stl" scale="0.001 0.001 0.001"/>
        </geometry>
        <material name="silver_default"/>
      </visual>
      <collision>
        <origin rpy="0 0 0" xyz="-0.0 -4e-06 -0.074366"/>
        <geometry>
          <mesh filename="package://amber_urdf_description/meshes/DOF1_LINK_1.stl" scale="0.001 0.001 0.001"/>
        </geometry>
      </collision>
    </link>

    <link name="${prefix}DOF2_1">
      <inertial>
        <origin rpy="0 0 0" xyz="-3.1921216491684105e-08 -0.011679501464314974 0.04696474149032967"/>
        <mass value="0.5984706718739643"/>
        <inertia ixx="0.001836" ixy="0.0" ixz="-0.0" iyy="0.001772" iyz="-0.000265" izz="0.000381"/>
      </inertial>
      <visual>
        <origin rpy="0 0 0" xyz="0.0 0.024996 -0.155566"/>
        <geometry>
          <mesh filename="package://amber_urdf_description/meshes/DOF2_1.stl" scale="0.001 0.001 0.001"/>
        </geometry>
        <material name="silver_default"/>
      </visual>
      <collision>
        <origin rpy="0 0 0" xyz="0.0 0.024996 -0.155566"/>
        <geometry>
          <mesh filename="package://amber_urdf_description/meshes/DOF2_1.stl" scale="0.001 0.001 0.001"/>
        </geometry>
      </collision>
    </link>

    <link name="${prefix}DOF3_MOTOR_1">
      <inertial>
        <origin rpy="0 0 0" xyz="7.926931010823914e-05 3.749110346027253e-05 -0.0313458911509952"/>
        <mass value="0.5847003223149023"/>
        <inertia ixx="0.000404" ixy="0.0" ixz="2e-06" iyy="0.00039" iyz="1e-06" izz="0.000324"/>
      </inertial>
      <visual>
        <origin rpy="0 0 0" xyz="0.0 -0.000504 -0.278463"/>
        <geometry>
          <mesh filename="package://amber_urdf_description/meshes/DOF3_MOTOR_1.stl" scale="0.001 0.001 0.001"/>
        </geometry>
        <material name="silver_default"/>
      </visual>
      <collision>
        <origin rpy="0 0 0" xyz="0.0 -0.000504 -0.278463"/>
        <geometry>
          <mesh filename="package://amber_urdf_description/meshes/DOF3_MOTOR_1.stl" scale="0.001 0.001 0.001"/>
        </geometry>
      </collision>
    </link>

    <link name="${prefix}DOF3_LINK_1">
      <inertial>
        <origin rpy="0 0 0" xyz="-5.21122742451035e-06 -0.004978087820401388 0.07040264166980847"/>
        <mass value="0.935292940405524"/>
        <inertia ixx="0.001224" ixy="-0.0" ixz="0.0" iyy="0.001136" iyz="4.3e-05" izz="0.00072"/>
      </inertial>
      <visual>
        <origin rpy="0 0 0" xyz="0.0 -0.000504 -0.283463"/>
        <geometry>
          <mesh filename="package://amber_urdf_description/meshes/DOF3_LINK_1.stl" scale="0.001 0.001 0.001"/>
        </geometry>
        <material name="silver_default"/>
      </visual>
      <collision>
        <origin rpy="0 0 0" xyz="0.0 -0.000504 -0.283463"/>
        <geometry>
          <mesh filename="package://amber_urdf_description/meshes/DOF3_LINK_1.stl" scale="0.001 0.001 0.001"/>
        </geometry>
      </collision>
    </link>

    <link name="${prefix}DOF4_1">
      <inertial>
        <origin rpy="0 0 0" xyz="2.9261458020017447e-08 0.011679309041134928 0.04696395208618592"/>
        <mass value="0.5984706718739643"/>
        <inertia ixx="0.001836" ixy="0.0" ixz="0.0" iyy="0.001772" iyz="0.000265" izz="0.000381"/>
      </inertial>
      <visual>
        <origin rpy="0 0 0" xyz="0.0 -0.025504 -0.364963"/>
        <geometry>
          <mesh filename="package://amber_urdf_description/meshes/DOF4_1.stl" scale="0.001 0.001 0.001"/>
        </geometry>
        <material name="silver_default"/>
      </visual>
      <collision>
        <origin rpy="0 0 0" xyz="0.0 -0.025504 -0.364963"/>
        <geometry>
          <mesh filename="package://amber_urdf_description/meshes/DOF4_1.stl" scale="0.001 0.001 0.001"/>
        </geometry>
      </collision>
    </link>

    <link name="${prefix}DOF5_MOTOR_1">
      <inertial>
        <origin rpy="0 0 0" xyz="-7.92719712862473e-05 -3.768352768190082e-05 -0.0313456805561112"/>
        <mass value="0.5847003223149023"/>
        <inertia ixx="0.000404" ixy="0.0" ixz="-2e-06" iyy="0.00039" iyz="-1e-06" izz="0.000324"/>
      </inertial>
      <visual>
        <origin rpy="0 0 0" xyz="-0.0 -4e-06 -0.487859"/>
        <geometry>
          <mesh filename="package://amber_urdf_description/meshes/DOF5_MOTOR_1.stl" scale="0.001 0.001 0.001"/>
        </geometry>
        <material name="silver_default"/>
      </visual>
      <collision>
        <origin rpy="0 0 0" xyz="-0.0 -4e-06 -0.487859"/>
        <geometry>
          <mesh filename="package://amber_urdf_description/meshes/DOF5_MOTOR_1.stl" scale="0.001 0.001 0.001"/>
        </geometry>
      </collision>
    </link>

    <link name="${prefix}DOF5_link_1">
      <inertial>
        <origin rpy="0 0 0" xyz="5.208648522717918e-06 0.004977895391692929 0.07010285226492913"/>
        <mass value="0.935292940405524"/>
        <inertia ixx="0.001224" ixy="-0.0" ixz="-0.0" iyy="0.001136" iyz="-4.3e-05" izz="0.00072"/>
      </inertial>
      <visual>
        <origin rpy="0 0 0" xyz="-0.0 -4e-06 -0.492859"/>
        <geometry>
          <mesh filename="package://amber_urdf_description/meshes/DOF5_link_1.stl" scale="0.001 0.001 0.001"/>
        </geometry>
        <material name="silver_default"/>
      </visual>
      <collision>
        <origin rpy="0 0 0" xyz="-0.0 -4e-06 -0.492859"/>
        <geometry>
          <mesh filename="package://amber_urdf_description/meshes/DOF5_link_1.stl" scale="0.001 0.001 0.001"/>
        </geometry>
      </collision>
    </link>

    <link name="${prefix}DOF6_LINK_1">
      <inertial>
        <origin rpy="0 0 0" xyz="-3.17560020832447e-08 -0.011679501474184246 0.04696416267915482"/>
        <mass value="0.5984706718739643"/>
        <inertia ixx="0.001836" ixy="0.0" ixz="-0.0" iyy="0.001772" iyz="-0.000265" izz="0.000381"/>
      </inertial>
      <visual>
        <origin rpy="0 0 0" xyz="-0.0 0.024996 -0.574059"/>
        <geometry>
          <mesh filename="package://amber_urdf_description/meshes/DOF6_LINK_1.stl" scale="0.001 0.001 0.001"/>
        </geometry>
        <material name="silver_default"/>
      </visual>
      <collision>
        <origin rpy="0 0 0" xyz="-0.0 0.024996 -0.574059"/>
        <geometry>
          <mesh filename="package://amber_urdf_description/meshes/DOF6_LINK_1.stl" scale="0.001 0.001 0.001"/>
        </geometry>
      </collision>
    </link>

    <link name="${prefix}DOF7_MOTOR_1">
      <inertial>
        <origin rpy="0 0 0" xyz="7.926952865318467e-05 3.749109242478111e-05 -0.03134546996129095"/>
        <mass value="0.5847003223149023"/>
        <inertia ixx="0.000404" ixy="0.0" ixz="2e-06" iyy="0.00039" iyz="1e-06" izz="0.000324"/>
      </inertial>
      <visual>
        <origin rpy="0 0 0" xyz="0.0 -0.000504 -0.696955"/>
        <geometry>
          <mesh filename="package://amber_urdf_description/meshes/DOF7_MOTOR_1.stl" scale="0.001 0.001 0.001"/>
        </geometry>
        <material name="silver_default"/>
      </visual>
      <collision>
        <origin rpy="0 0 0" xyz="0.0 -0.000504 -0.696955"/>
        <geometry>
          <mesh filename="package://amber_urdf_description/meshes/DOF7_MOTOR_1.stl" scale="0.001 0.001 0.001"/>
        </geometry>
      </collision>
    </link>

    <link name="${prefix}TOP_1">
      <inertial>
        <origin rpy="0 0 0" xyz="-4.963925281376204e-07 -0.00019582783329597517 0.01611980646593192"/>
        <mass value="0.15302388632599126"/>
        <inertia ixx="4.6e-05" ixy="0.0" ixz="0.0" iyy="5e-05" iyz="0.0" izz="5.5e-05"/>
      </inertial>
      <visual>
        <origin rpy="0 0 0" xyz="0.0 -0.000504 -0.701955"/>
        <geometry>
          <mesh filename="package://amber_urdf_description/meshes/TOP_1.stl" scale="0.001 0.001 0.001"/>
        </geometry>
        <material name="silver_default"/>
      </visual>
      <collision>
        <origin rpy="0 0 0" xyz="0.0 -0.000504 -0.701955"/>
        <geometry>
          <mesh filename="package://amber_urdf_description/meshes/TOP_1.stl" scale="0.001 0.001 0.001"/>
        </geometry>
      </collision>
    </link>


    <joint name="${prefix}Rigid1" type="fixed">
      <origin rpy="0 0 0" xyz="0.0 4e-06 0.069966"/>
      <parent link="${prefix}base_link"/>
      <child link="${prefix}DOF1_1"/>
    </joint>

    <joint name="${prefix}Rev2" type="continuous">
      <origin rpy="0 0 0" xyz="0.0 4e-06 0.074366"/>
      <parent link="${prefix}base_link"/>
      <child link="${prefix}DOF1_LINK_1"/>
      <axis xyz="0.0 0.0 1.0"/>
    </joint>

    <joint name="${prefix}Rev3" type="continuous">
      <origin rpy="0 0 0" xyz="-0.0 -0.025 0.0812"/>
      <parent link="${prefix}DOF1_LINK_1"/>
      <child link="${prefix}DOF2_1"/>
      <axis xyz="0.0 1.0 -0.0"/>
    </joint>

    <joint name="${prefix}Rigid5" type="fixed">
      <origin rpy="0 0 0" xyz="0.0 0.0255 0.122897"/>
      <parent link="${prefix}DOF2_1"/>
      <child link="${prefix}DOF3_MOTOR_1"/>
    </joint>

    <joint name="${prefix}Rev6" type="continuous">
      <origin rpy="0 0 0" xyz="0.0 0.0255 0.127897"/>
      <parent link="${prefix}DOF2_1"/>
      <child link="${prefix}DOF3_LINK_1"/>
      <axis xyz="0.0 -0.0 -1.0"/>
    </joint>

    <joint name="${prefix}Rev7" type="continuous">
      <origin rpy="0 0 0" xyz="0.0 0.025 0.0815"/>
      <parent link="${prefix}DOF3_LINK_1"/>
      <child link="${prefix}DOF4_1"/>
      <axis xyz="0.0 -1.0 -0.0"/>
    </joint>

    <joint name="${prefix}Rigid8" type="fixed">
      <origin rpy="0 0 0" xyz="0.0 -0.0255 0.122896"/>
      <parent link="${prefix}DOF4_1"/>
      <child link="${prefix}DOF5_MOTOR_1"/>
    </joint>

    <joint name="${prefix}Rev9" type="continuous">
      <origin rpy="0 0 0" xyz="0.0 -0.0255 0.127896"/>
      <parent link="${prefix}DOF4_1"/>
      <child link="${prefix}DOF5_link_1"/>
      <axis xyz="-0.0 0.0 -1.0"/>
    </joint>

    <joint name="${prefix}Rev10" type="continuous">
      <origin rpy="0 0 0" xyz="0.0 -0.025 0.0812"/>
      <parent link="${prefix}DOF5_link_1"/>
      <child link="${prefix}DOF6_LINK_1"/>
      <axis xyz="0.0 1.0 0.0"/>
    </joint>

    <joint name="${prefix}Rigid11" type="fixed">
      <origin rpy="0 0 0" xyz="-0.0 0.0255 0.122896"/>
      <parent link="${prefix}DOF6_LINK_1"/>
      <child link="${prefix}DOF7_MOTOR_1"/>
    </joint>

    <joint name="${prefix}Rigid12" type="fixed">
      <origin rpy="0 0 0" xyz="-0.0 0.0255 0.127896"/>
      <parent link="${prefix}DOF6_LINK_1"/>
      <child link="${prefix}TOP_1"/>
    </joint>

  </xacro:macro>

</robot>
